Workbook

Sheet Dashboard
A1: Campus Class Timetable Dashboard
A4: OVERALL SNAPSHOT (all classes currently in the timetable)
A5: TOTAL CLASS SLOTS (all statuses) | C5: PHYSICAL CLASSES | E5: HYBRID CLASSES | G5: ONLINE CLASSES | I5: COMPLETED CLASSES | K5: UPCOMING CLASSES
A6: ='Class Schedule Analysis'!A165-'Class Schedule Analysis'!A3+1 -> 163 | C6: =COUNTIF('Class Schedule Analysis'!$M$3:$M$165,"Physical") -> 124 | E6: =COUNTIF('Class Schedule Analysis'!$M$3:$M$165,"Hybrid") -> 29 | G6: =COUNTIF('Class Schedule Analysis'!$M$3:$M$165,"Online") -> 8 | I6: =COUNTIF('Class Schedule Analysis'!$S$3:$S$165,"Completed") -> 34 | K6: =COUNTIF('Class Schedule Analysis'!$S$3:$S$165,"Upcoming") -> 0
A8: THIS MONTH — PLANNED CLASSES & LECTURE HALL GAP (auto-updates from TODAY())
A9: PHYSICAL PLANNED (this month) | C9: HYBRID PLANNED (this month) | E9: ONLINE PLANNED (this month) | G9: PHYSICAL GAP (halls free, this month) | I9: HYBRID GAP (halls free, this month) | K9: ONLINE GAP (halls free, this month)
A10: =INDEX('Monthly Summary'!$B$4:$B$25,MATCH(DATE(YEAR(TODAY()),MONTH(TODAY()),1),'Monthly Summary'!$A$4:$A$25,0)) -> 349 | C10: =INDEX('Monthly Summary'!$C$4:$C$25,MATCH(DATE(YEAR(TODAY()),MONTH(TODAY()),1),'Monthly Summary'!$A$4:$A$25,0)) -> 44 | E10: =INDEX('Monthly Summary'!$D$4:$D$25,MATCH(DATE(YEAR(TODAY()),MONTH(TODAY()),1),'Monthly Summary'!$A$4:$A$25,0)) -> 18 | G10: =INDEX('Monthly Summary'!$F$4:$F$25,MATCH(DATE(YEAR(TODAY()),MONTH(TODAY()),1),'Monthly Summary'!$A$4:$A$25,0)) -> 7 | I10: =INDEX('Monthly Summary'!$G$4:$G$25,MATCH(DATE(YEAR(TODAY()),MONTH(TODAY()),1),'Monthly Summary'!$A$4:$A$25,0)) -> 17 | K10: =INDEX('Monthly Summary'!$H$4:$H$25,MATCH(DATE(YEAR(TODAY()),MONTH(TODAY()),1),'Monthly Summary'!$A$4:$A$25,0)) -> 22
A36: Mode | B36: Halls Used | C36: Halls Free (Gap)
A37: Physical | B37: =26-C37 -> 19 | C37: =G10 -> 7
A38: Hybrid | B38: =26-C38 -> 9 | C38: =I10 -> 17
A39: Online | B39: =26-C39 -> 4 | C39: =K10 -> 22

Sheet Monthly Summary
A1: Monthly Class Summary — Planned Classes & Lecture Hall Gap by Mode
A3: Month | B3: Physical Planned | C3: Hybrid Planned | D3: Online Planned | E3: Total Planned | F3: Physical Gap (halls free) | G3: Hybrid Gap (halls free) | H3: Online Gap (halls free)
A4: 45962 | B4: =SUMPRODUCT(('Monthly Occurrences (Support)'!$D$4:$D$166="Physical")*('Monthly Occurrences (Support)'!$G$4:$G$166)) -> 4 | C4: =SUMPRODUCT(('Monthly Occurrences (Support)'!$D$4:$D$166="Hybrid")*('Monthly Occurrences (Support)'!$G$4:$G$166)) -> 0 | D4: =SUMPRODUCT(('Monthly Occurrences (Support)'!$D$4:$D$166="Online")*('Monthly Occurrences (Support)'!$G$4:$G$166)) -> 0 | E4: =B4+C4+D4 -> 4 | F4: ='Lecture Hall Availability'!B33 -> 25 | G4: ='Lecture Hall Availability'!B64 -> 26 | H4: ='Lecture Hall Availability'!B95 -> 26
A5: 45992 | B5: =SUMPRODUCT(('Monthly Occurrences (Support)'!$D$4:$D$166="Physical")*('Monthly Occurrences (Support)'!$H$4:$H$166)) -> 4 | C5: =SUMPRODUCT(('Monthly Occurrences (Support)'!$D$4:$D$166="Hybrid")*('Monthly Occurrences (Support)'!$H$4:$H$166)) -> 0 | D5: =SUMPRODUCT(('Monthly Occurrences (Support)'!$D$4:$D$166="Online")*('Monthly Occurrences (Support)'!$H$4:$H$166)) -> 0 | E5: =B5+C5+D5 -> 4 | F5: ='Lecture Hall Availability'!C33 -> 25 | G5: ='Lecture Hall Availability'!C64 -> 26 | H5: ='Lecture Hall Availability'!C95 -> 26
A6: 46023 | B6: =SUMPRODUCT(('Monthly Occurrences (Support)'!$D$4:$D$166="Physical")*('Monthly Occurrences (Support)'!$I$4:$I$166)) -> 5 | C6: =SUMPRODUCT(('Monthly Occurrences (Support)'!$D$4:$D$166="Hybrid")*('Monthly Occurrences (Support)'!$I$4:$I$166)) -> 0 | D6: =SUMPRODUCT(('Monthly Occurrences (Support)'!$D$4:$D$166="Online")*('Monthly Occurrences (Support)'!$I$4:$I$166)) -> 0 | E6: =B6+C6+D6 -> 5 | F6: ='Lecture Hall Availability'!D33 -> 25 | G6: ='Lecture Hall Availability'!D64 -> 26 | H6: ='Lecture Hall Availability'!D95 -> 26
A7: 46054 | B7: =SUMPRODUCT(('Monthly Occurrences (Support)'!$D$4:$D$166="Physical")*('Monthly Occurrences (Support)'!$J$4:$J$166)) -> 4 | C7: =SUMPRODUCT(('Monthly Occurrences (Support)'!$D$4:$D$166="Hybrid")*('Monthly Occurrences (Support)'!$J$4:$J$166)) -> 0 | D7: =SUMPRODUCT(('Monthly Occurrences (Support)'!$D$4:$D$166="Online")*('Monthly Occurrences (Support)'!$J$4:$J$166)) -> 0 | E7: =B7+C7+D7 -> 4 | F7: ='Lecture Hall Availability'!E33 -> 25 | G7: ='Lecture Hall Availability'!E64 -> 26 | H7: ='Lecture Hall Availability'!E95 -> 26
A8: 46082 | B8: =SUMPRODUCT(('Monthly Occurrences (Support)'!$D$4:$D$166="Physical")*('Monthly Occurrences (Support)'!$K$4:$K$166)) -> 40 | C8: =SUMPRODUCT(('Monthly Occurrences (Support)'!$D$4:$D$166="Hybrid")*('Monthly Occurrences (Support)'!$K$4:$K$166)) -> 6 | D8: =SUMPRODUCT(('Monthly Occurrences (Support)'!$D$4:$D$166="Online")*('Monthly Occurrences (Support)'!$K$4:$K$166)) -> 2 | E8: =B8+C8+D8 -> 48 | F8: ='Lecture Hall Availability'!F33 -> 15 | G8: ='Lecture Hall Availability'!F64 -> 25 | H8: ='Lecture Hall Availability'!F95 -> 24
A9: 46113 | B9: =SUMPRODUCT(('Monthly Occurrences (Support)'!$D$4:$D$166="Physical")*('Monthly Occurrences (Support)'!$L$4:$L$166)) -> 128 | C9: =SUMPRODUCT(('Monthly Occurrences (Support)'!$D$4:$D$166="Hybrid")*('Monthly Occurrences (Support)'!$L$4:$L$166)) -> 25 | D9: =SUMPRODUCT(('Monthly Occurrences (Support)'!$D$4:$D$166="Online")*('Monthly Occurrences (Support)'!$L$4:$L$166)) -> 8 | E9: =B9+C9+D9 -> 161 | F9: ='Lecture Hall Availability'!G33 -> 11 | G9: ='Lecture Hall Availability'!G64 -> 22 | H9: ='Lecture Hall Availability'!G95 -> 24
A10: 46143 | B10: =SUMPRODUCT(('Monthly Occurrences (Support)'!$D$4:$D$166="Physical")*('Monthly Occurrences (Support)'!$M$4:$M$166)) -> 192 | C10: =SUMPRODUCT(('Monthly Occurrences (Support)'!$D$4:$D$166="Hybrid")*('Monthly Occurrences (Support)'!$M$4:$M$166)) -> 52 | D10: =SUMPRODUCT(('Monthly Occurrences (Support)'!$D$4:$D$166="Online")*('Monthly Occurrences (Support)'!$M$4:$M$166)) -> 10 | E10: =B10+C10+D10 -> 254 | F10: ='Lecture Hall Availability'!H33 -> 10 | G10: ='Lecture Hall Availability'!H64 -> 19 | H10: ='Lecture Hall Availability'!H95 -> 24
A11: 46174 | B11: =SUMPRODUCT(('Monthly Occurrences (Support)'!$D$4:$D$166="Physical")*('Monthly Occurrences (Support)'!$N$4:$N$166)) -> 209 | C11: =SUMPRODUCT(('Monthly Occurrences (Support)'!$D$4:$D$166="Hybrid")*('Monthly Occurrences (Support)'!$N$4:$N$166)) -> 82 | D11: =SUMPRODUCT(('Monthly Occurrences (Support)'!$D$4:$D$166="Online")*('Monthly Occurrences (Support)'!$N$4:$N$166)) -> 8 | E11: =B11+C11+D11 -> 299 | F11: ='Lecture Hall Availability'!I33 -> 9 | G11: ='Lecture Hall Availability'!I64 -> 14 | H11: ='Lecture Hall Availability'!I95 -> 24
A12: 46204 | B12: =SUMPRODUCT(('Monthly Occurrences (Support)'!$D$4:$D$166="Physical")*('Monthly Occurrences (Support)'!$O$4:$O$166)) -> 392 | C12: =SUMPRODUCT(('Monthly Occurrences (Support)'!$D$4:$D$166="Hybrid")*('Monthly Occurrences (Support)'!$O$4:$O$166)) -> 96 | D12: =SUMPRODUCT(('Monthly Occurrences (Support)'!$D$4:$D$166="Online")*('Monthly Occurrences (Support)'!$O$4:$O$166)) -> 17 | E12: =B12+C12+D12 -> 505 | F12: ='Lecture Hall Availability'!J33 -> 6 | G12: ='Lecture Hall Availability'!J64 -> 14 | H12: ='Lecture Hall Availability'!J95 -> 22
A13: 46235 | B13: =SUMPRODUCT(('Monthly Occurrences (Support)'!$D$4:$D$166="Physical")*('Monthly Occurrences (Support)'!$P$4:$P$166)) -> 415 | C13: =SUMPRODUCT(('Monthly Occurrences (Support)'!$D$4:$D$166="Hybrid")*('Monthly Occurrences (Support)'!$P$4:$P$166)) -> 84 | D13: =SUMPRODUCT(('Monthly Occurrences (Support)'!$D$4:$D$166="Online")*('Monthly Occurrences (Support)'!$P$4:$P$166)) -> 25 | E13: =B13+C13+D13 -> 524 | F13: ='Lecture Hall Availability'!K33 -> 7 | G13: ='Lecture Hall Availability'!K64 -> 14 | H13: ='Lecture Hall Availability'!K95 -> 22
A14: 46266 | B14: =SUMPRODUCT(('Monthly Occurrences (Support)'!$D$4:$D$166="Physical")*('Monthly Occurrences (Support)'!$Q$4:$Q$166)) -> 349 | C14: =SUMPRODUCT(('Monthly Occurrences (Support)'!$D$4:$D$166="Hybrid")*('Monthly Occurrences (Support)'!$Q$4:$Q$166)) -> 44 | D14: =SUMPRODUCT(('Monthly Occurrences (Support)'!$D$4:$D$166="Online")*('Monthly Occurrences (Support)'!$Q$4:$Q$166)) -> 18 | E14: =B14+C14+D14 -> 411 | F14: ='Lecture Hall Availability'!L33 -> 7 | G14: ='Lecture Hall Availability'!L64 -> 17 | H14: ='Lecture Hall Availability'!L95 -> 22
A15: 46296 | B15: =SUMPRODUCT(('Monthly Occurrences (Support)'!$D$4:$D$166="Physical")*('Monthly Occurrences (Support)'!$R$4:$R$166)) -> 325 | C15: =SUMPRODUCT(('Monthly Occurrences (Support)'!$D$4:$D$166="Hybrid")*('Monthly Occurrences (Support)'!$R$4:$R$166)) -> 12 | D15: =SUMPRODUCT(('Monthly Occurrences (Support)'!$D$4:$D$166="Online")*('Monthly Occurrences (Support)'!$R$4:$R$166)) -> 20 | E15: =B15+C15+D15 -> 357 | F15: ='Lecture Hall Availability'!M33 -> 7 | G15: ='Lecture Hall Availability'!M64 -> 24 | H15: ='Lecture Hall Availability'!M95 -> 23
A16: 46327 | B16: =SUMPRODUCT(('Monthly Occurrences (Support)'!$D$4:$D$166="Physical")*('Monthly Occurrences (Support)'!$S$4:$S$166)) -> 193 | C16: =SUMPRODUCT(('Monthly Occurrences (Support)'!$D$4:$D$166="Hybrid")*('Monthly Occurrences (Support)'!$S$4:$S$166)) -> 4 | D16: =SUMPRODUCT(('Monthly Occurrences (Support)'!$D$4:$D$166="Online")*('Monthly Occurrences (Support)'!$S$4:$S$166)) -> 8 | E16: =B16+C16+D16 -> 205 | F16: ='Lecture Hall Availability'!N33 -> 8 | G16: ='Lecture Hall Availability'!N64 -> 25 | H16: ='Lecture Hall Availability'!N95 -> 25
A17: 46357 | B17: =SUMPRODUCT(('Monthly Occurrences (Support)'!$D$4:$D$166="Physical")*('Monthly Occurrences (Support)'!$T$4:$T$166)) -> 92 | C17: =SUMPRODUCT(('Monthly Occurrences (Support)'!$D$4:$D$166="Hybrid")*('Monthly Occurrences (Support)'!$T$4:$T$166)) -> 1 | D17: =SUMPRODUCT(('Monthly Occurrences (Support)'!$D$4:$D$166="Online")*('Monthly Occurrences (Support)'!$T$4:$T$166)) -> 3 | E17: =B17+C17+D17 -> 96 | F17: ='Lecture Hall Availability'!O33 -> 12 | G17: ='Lecture Hall Availability'!O64 -> 25 | H17: ='Lecture Hall Availability'!O95 -> 25
A18: 46388 | B18: =SUMPRODUCT(('Monthly Occurrences (Support)'!$D$4:$D$166="Physical")*('Monthly Occurrences (Support)'!$U$4:$U$166)) -> 39 | C18: =SUMPRODUCT(('Monthly Occurrences (Support)'!$D$4:$D$166="Hybrid")*('Monthly Occurrences (Support)'!$U$4:$U$166)) -> 0 | D18: =SUMPRODUCT(('Monthly Occurrences (Support)'!$D$4:$D$166="Online")*('Monthly Occurrences (Support)'!$U$4:$U$166)) -> 0 | E18: =B18+C18+D18 -> 39 | F18: ='Lecture Hall Availability'!P33 -> 23 | G18: ='Lecture Hall Availability'!P64 -> 26 | H18: ='Lecture Hall Availability'!P95 -> 26
A19: 46419 | B19: =SUMPRODUCT(('Monthly Occurrences (Support)'!$D$4:$D$166="Physical")*('Monthly Occurrences (Support)'!$V$4:$V$166)) -> 36 | C19: =SUMPRODUCT(('Monthly Occurrences (Support)'!$D$4:$D$166="Hybrid")*('Monthly Occurrences (Support)'!$V$4:$V$166)) -> 0 | D19: =SUMPRODUCT(('Monthly Occurrences (Support)'!$D$4:$D$166="Online")*('Monthly Occurrences (Support)'!$V$4:$V$166)) -> 0 | E19: =B19+C19+D19 -> 36 | F19: ='Lecture Hall Availability'!Q33 -> 24 | G19: ='Lecture Hall Availability'!Q64 -> 26 | H19: ='Lecture Hall Availability'!Q95 -> 26
A20: 46447 | B20: =SUMPRODUCT(('Monthly Occurrences (Support)'!$D$4:$D$166="Physical")*('Monthly Occurrences (Support)'!$W$4:$W$166)) -> 42 | C20: =SUMPRODUCT(('Monthly Occurrences (Support)'!$D$4:$D$166="Hybrid")*('Monthly Occurrences (Support)'!$W$4:$W$166)) -> 0 | D20: =SUMPRODUCT(('Monthly Occurrences (Support)'!$D$4:$D$166="Online")*('Monthly Occurrences (Support)'!$W$4:$W$166)) -> 0 | E20: =B20+C20+D20 -> 42 | F20: ='Lecture Hall Availability'!R33 -> 24 | G20: ='Lecture Hall Availability'!R64 -> 26 | H20: ='Lecture Hall Availability'!R95 -> 26
A21: 46478 | B21: =SUMPRODUCT(('Monthly Occurrences (Support)'!$D$4:$D$166="Physical")*('Monthly Occurrences (Support)'!$X$4:$X$166)) -> 39 | C21: =SUMPRODUCT(('Monthly Occurrences (Support)'!$D$4:$D$166="Hybrid")*('Monthly Occurrences (Support)'!$X$4:$X$166)) -> 0 | D21: =SUMPRODUCT(('Monthly Occurrences (Support)'!$D$4:$D$166="Online")*('Monthly Occurrences (Support)'!$X$4:$X$166)) -> 0 | E21: =B21+C21+D21 -> 39 | F21: ='Lecture Hall Availability'!S33 -> 24 | G21: ='Lecture Hall Availability'!S64 -> 26 | H21: ='Lecture Hall Availability'!S95 -> 26
A22: 46508 | B22: =SUMPRODUCT(('Monthly Occurrences (Support)'!$D$4:$D$166="Physical")*('Monthly Occurrences (Support)'!$Y$4:$Y$166)) -> 38 | C22: =SUMPRODUCT(('Monthly Occurrences (Support)'!$D$4:$D$166="Hybrid")*('Monthly Occurrences (Support)'!$Y$4:$Y$166)) -> 0 | D22: =SUMPRODUCT(('Monthly Occurrences (Support)'!$D$4:$D$166="Online")*('Monthly Occurrences (Support)'!$Y$4:$Y$166)) -> 0 | E22: =B22+C22+D22 -> 38 | F22: ='Lecture Hall Availability'!T33 -> 24 | G22: ='Lecture Hall Availability'!T64 -> 26 | H22: ='Lecture Hall Availability'!T95 -> 26
A23: 46539 | B23: =SUMPRODUCT(('Monthly Occurrences (Support)'!$D$4:$D$166="Physical")*('Monthly Occurrences (Support)'!$Z$4:$Z$166)) -> 40 | C23: =SUMPRODUCT(('Monthly Occurrences (Support)'!$D$4:$D$166="Hybrid")*('Monthly Occurrences (Support)'!$Z$4:$Z$166)) -> 0 | D23: =SUMPRODUCT(('Monthly Occurrences (Support)'!$D$4:$D$166="Online")*('Monthly Occurrences (Support)'!$Z$4:$Z$166)) -> 0 | E23: =B23+C23+D23 -> 40 | F23: ='Lecture Hall Availability'!U33 -> 24 | G23: ='Lecture Hall Availability'!U64 -> 26 | H23: ='Lecture Hall Availability'!U95 -> 26
A24: 46569 | B24: =SUMPRODUCT(('Monthly Occurrences (Support)'!$D$4:$D$166="Physical")*('Monthly Occurrences (Support)'!$AA$4:$AA$166)) -> 39 | C24: =SUMPRODUCT(('Monthly Occurrences (Support)'!$D$4:$D$166="Hybrid")*('Monthly Occurrences (Support)'!$AA$4:$AA$166)) -> 0 | D24: =SUMPRODUCT(('Monthly Occurrences (Support)'!$D$4:$D$166="Online")*('Monthly Occurrences (Support)'!$AA$4:$AA$166)) -> 0 | E24: =B24+C24+D24 -> 39 | F24: ='Lecture Hall Availability'!V33 -> 24 | G24: ='Lecture Hall Availability'!V64 -> 26 | H24: ='Lecture Hall Availability'!V95 -> 26
A25: 46600 | B25: =SUMPRODUCT(('Monthly Occurrences (Support)'!$D$4:$D$166="Physical")*('Monthly Occurrences (Support)'!$AB$4:$AB$166)) -> 40 | C25: =SUMPRODUCT(('Monthly Occurrences (Support)'!$D$4:$D$166="Hybrid")*('Monthly Occurrences (Support)'!$AB$4:$AB$166)) -> 0 | D25: =SUMPRODUCT(('Monthly Occurrences (Support)'!$D$4:$D$166="Online")*('Monthly Occurrences (Support)'!$AB$4:$AB$166)) -> 0 | E25: =B25+C25+D25 -> 40 | F25: ='Lecture Hall Availability'!W33 -> 24 | G25: ='Lecture Hall Availability'!W64 -> 26 | H25: ='Lecture Hall Availability'!W95 -> 26
A26: TOTAL (sum of months) | B26: =SUM(B4:B25) -> 2665 | C26: =SUM(C4:C25) -> 406 | D26: =SUM(D4:D25) -> 119 | E26: =SUM(E4:E25) -> 3190

Sheet Lecture Hall Availability
A1: Lecture Hall Availability — Monthly Hall Usage by Class Mode
A4: PHYSICAL — Sessions per Month by Lecture Hall
A5: Lecture Hall | B5: 45962 | C5: 45992 | D5: 46023 | E5: 46054 | F5: 46082 | G5: 46113 | H5: 46143 | I5: 46174 | J5: 46204 | K5: 46235 | L5: 46266 | M5: 46296 | N5: 46327 | O5: 46357 | P5: 46388 | Q5: 46419 | R5: 46447 | S5: 46478 | T5: 46508 | U5: 46539 | V5: 46569 | W5: 46600
A6: AUDITORIUM | B6: =SUMPRODUCT(('Monthly Occurrences (Support)'!$C$4:$C$166=$A6)*('Monthly Occurrences (Support)'!$D$4:$D$166="Physical")*('Monthly Occurrences (Support)'!$G$4:$G$166)) -> 0 | C6: =SUMPRODUCT(('Monthly Occurrences (Support)'!$C$4:$C$166=$A6)*('Monthly Occurrences (Support)'!$D$4:$D$166="Physical")*('Monthly Occurrences (Support)'!$H$4:$H$166)) -> 0 | D6: =SUMPRODUCT(('Monthly Occurrences (Support)'!$C$4:$C$166=$A6)*('Monthly Occurrences (Support)'!$D$4:$D$166="Physical")*('Monthly Occurrences (Support)'!$I$4:$I$166)) -> 0 | E6: =SUMPRODUCT(('Monthly Occurrences (Support)'!$C$4:$C$166=$A6)*('Monthly Occurrences (Support)'!$D$4:$D$166="Physical")*('Monthly Occurrences (Support)'!$J$4:$J$166)) -> 0 | F6: =SUMPRODUCT(('Monthly Occurrences (Support)'!$C$4:$C$166=$A6)*('Monthly Occurrences (Support)'!$D$4:$D$166="Physical")*('Monthly Occurrences (Support)'!$K$4:$K$166)) -> 0 | G6: =SUMPRODUCT(('Monthly Occurrences (Support)'!$C$4:$C$166=$A6)*('Monthly Occurrences (Support)'!$D$4:$D$166="Physical")*('Monthly Occurrences (Support)'!$L$4:$L$166)) -> 0 | H6: =SUMPRODUCT(('Monthly Occurrences (Support)'!$C$4:$C$166=$A6)*('Monthly Occurrences (Support)'!$D$4:$D$166="Physical")*('Monthly Occurrences (Support)'!$M$4:$M$166)) -> 0 | I6: =SUMPRODUCT(('Monthly Occurrences (Support)'!$C$4:$C$166=$A6)*('Monthly Occurrences (Support)'!$D$4:$D$166="Physical")*('Monthly Occurrences (Support)'!$N$4:$N$166)) -> 0 | J6: =SUMPRODUCT(('Monthly Occurrences (Support)'!$C$4:$C$166=$A6)*('Monthly Occurrences (Support)'!$D$4:$D$166="Physical")*('Monthly Occurrences (Support)'!$O$4:$O$166)) -> 0 | K6: =SUMPRODUCT(('Monthly Occurrences (Support)'!$C$4:$C$166=$A6)*('Monthly Occurrences (Support)'!$D$4:$D$166="Physical")*('Monthly Occurrences (Support)'!$P$4:$P$166)) -> 0 | L6: =SUMPRODUCT(('Monthly Occurrences (Support)'!$C$4:$C$166=$A6)*('Monthly Occurrences (Support)'!$D$4:$D$166="Physical")*('Monthly Occurrences (Support)'!$Q$4:$Q$166)) -> 0 | M6: =SUMPRODUCT(('Monthly Occurrences (Support)'!$C$4:$C$166=$A6)*('Monthly Occurrences (Support)'!$D$4:$D$166="Physical")*('Monthly Occurrences (Support)'!$R$4:$R$166)) -> 0 | N6: =SUMPRODUCT(('Monthly Occurrences (Support)'!$C$4:$C$166=$A6)*('Monthly Occurrences (Support)'!$D$4:$D$166="Physical")*('Monthly Occurrences (Support)'!$S$4:$S$166)) -> 0 | O6: =SUMPRODUCT(('Monthly Occurrences (Support)'!$C$4:$C$166=$A6)*('Monthly Occurrences (Support)'!$D$4:$D$166="Physical")*('Monthly Occurrences (Support)'!$T$4:$T$166)) -> 0 | P6: =SUMPRODUCT(('Monthly Occurrences (Support)'!$C$4:$C$166=$A6)*('Monthly Occurrences (Support)'!$D$4:$D$166="Physical")*('Monthly Occurrences (Support)'!$U$4:$U$166)) -> 0 | Q6: =SUMPRODUCT(('Monthly Occurrences (Support)'!$C$4:$C$166=$A6)*('Monthly Occurrences (Support)'!$D$4:$D$166="Physical")*('Monthly Occurrences (Support)'!$V$4:$V$166)) -> 0 | R6: =SUMPRODUCT(('Monthly Occurrences (Support)'!$C$4:$C$166=$A6)*('Monthly Occurrences (Support)'!$D$4:$D$166="Physical")*('Monthly Occurrences (Support)'!$W$4:$W$166)) -> 0 | S6: =SUMPRODUCT(('Monthly Occurrences (Support)'!$C$4:$C$166=$A6)*('Monthly Occurrences (Support)'!$D$4:$D$166="Physical")*('Monthly Occurrences (Support)'!$X$4:$X$166)) -> 0 | T6: =SUMPRODUCT(('Monthly Occurrences (Support)'!$C$4:$C$166=$A6)*('Monthly Occurrences (Support)'!$D$4:$D$166="Physical")*('Monthly Occurrences (Support)'!$Y$4:$Y$166)) -> 0 | U6: =SUMPRODUCT(('Monthly Occurrences (Support)'!$C$4:$C$166=$A6)*('Monthly Occurrences (Support)'!$D$4:$D$166="Physical")*('Monthly Occurrences (Support)'!$Z$4:$Z$166)) -> 0 | V6: =SUMPRODUCT(('Monthly Occurrences (Support)'!$C$4:$C$166=$A6)*('Monthly Occurrences (Support)'!$D$4:$D$166="Physical")*('Monthly Occurrences (Support)'!$AA$4:$AA$166)) -> 0 | W6: =SUMPRODUCT(('Monthly Occurrences (Support)'!$C$4:$C$166=$A6)*('Monthly Occurrences (Support)'!$D$4:$D$166="Physical")*('Monthly Occurrences (Support)'!$AB$4:$AB$166)) -> 0
A7: EAST 304 | B7: =SUMPRODUCT(('Monthly Occurrences (Support)'!$C$4:$C$166=$A7)*('Monthly Occurrences (Support)'!$D$4:$D$166="Physical")*('Monthly Occurrences (Support)'!$G$4:$G$166)) -> 0 | C7: =SUMPRODUCT(('Monthly Occurrences (Support)'!$C$4:$C$166=$A7)*('Monthly Occurrences (Support)'!$D$4:$D$166="Physical")*('Monthly Occurrences (Support)'!$H$4:$H$166)) -> 0 | D7: =SUMPRODUCT(('Monthly Occurrences (Support)'!$C$4:$C$166=$A7)*('Monthly Occurrences (Support)'!$D$4:$D$166="Physical")*('Monthly Occurrences (Support)'!$I$4:$I$166)) -> 0 | E7: =SUMPRODUCT(('Monthly Occurrences (Support)'!$C$4:$C$166=$A7)*('Monthly Occurrences (Support)'!$D$4:$D$166="Physical")*('Monthly Occurrences (Support)'!$J$4:$J$166)) -> 0 | F7: =SUMPRODUCT(('Monthly Occurrences (Support)'!$C$4:$C$166=$A7)*('Monthly Occurrences (Support)'!$D$4:$D$166="Physical")*('Monthly Occurrences (Support)'!$K$4:$K$166)) -> 0 | G7: =SUMPRODUCT(('Monthly Occurrences (Support)'!$C$4:$C$166=$A7)*('Monthly Occurrences (Support)'!$D$4:$D$166="Physical")*('Monthly Occurrences (Support)'!$L$4:$L$166)) -> 0 | H7: =SUMPRODUCT(('Monthly Occurrences (Support)'!$C$4:$C$166=$A7)*('Monthly Occurrences (Support)'!$D$4:$D$166="Physical")*('Monthly Occurrences (Support)'!$M$4:$M$166)) -> 4 | I7: =SUMPRODUCT(('Monthly Occurrences (Support)'!$C$4:$C$166=$A7)*('Monthly Occurrences (Support)'!$D$4:$D$166="Physical")*('Monthly Occurrences (Support)'!$N$4:$N$166)) -> 4 | J7: =SUMPRODUCT(('Monthly Occurrences (Support)'!$C$4:$C$166=$A7)*('Monthly Occurrences (Support)'!$D$4:$D$166="Physical")*('Monthly Occurrences (Support)'!$O$4:$O$166)) -> 11 | K7: =SUMPRODUCT(('Monthly Occurrences (Support)'!$C$4:$C$166=$A7)*('Monthly Occurrences (Support)'!$D$4:$D$166="Physical")*('Monthly Occurrences (Support)'!$P$4:$P$166)) -> 12 | L7: =SUMPRODUCT(('Monthly Occurrences (Support)'!$C$4:$C$166=$A7)*('Monthly Occurrences (Support)'!$D$4:$D$166="Physical")*('Monthly Occurrences (Support)'!$Q$4:$Q$166)) -> 8 | M7: =SUMPRODUCT(('Monthly Occurrences (Support)'!$C$4:$C$166=$A7)*('Monthly Occurrences (Support)'!$D$4:$D$166="Physical")*('Monthly Occurrences (Support)'!$R$4:$R$166)) -> 10 | N7: =SUMPRODUCT(('Monthly Occurrences (Support)'!$C$4:$C$166=$A7)*('Monthly Occurrences (Support)'!$D$4:$D$166="Physical")*('Monthly Occurrences (Support)'!$S$4:$S$166)) -> 8 | O7: =SUMPRODUCT(('Monthly Occurrences (Support)'!$C$4:$C$166=$A7)*('Monthly Occurrences (Support)'!$D$4:$D$166="Physical")*('Monthly Occurrences (Support)'!$T$4:$T$166)) -> 3 | P7: =SUMPRODUCT(('Monthly Occurrences (Support)'!$C$4:$C$166=$A7)*('Monthly Occurrences (Support)'!$D$4:$D$166="Physical")*('Monthly Occurrences (Support)'!$U$4:$U$166)) -> 0 | Q7: =SUMPRODUCT(('Monthly Occurrences (Support)'!$C$4:$C$166=$A7)*('Monthly Occurrences (Support)'!$D$4:$D$166="Physical")*('Monthly Occurrences (Support)'!$V$4:$V$166)) -> 0 | R7: =SUMPRODUCT(('Monthly Occurrences (Support)'!$C$4:$C$166=$A7)*('Monthly Occurrences (Support)'!$D$4:$D$166="Physical")*('Monthly Occurrences (Support)'!$W$4:$W$166)) -> 0 | S7: =SUMPRODUCT(('Monthly Occurrences (Support)'!$C$4:$C$166=$A7)*('Monthly Occurrences (Support)'!$D$4:$D$166="Physical")*('Monthly Occurrences (Support)'!$X$4:$X$166)) -> 0 | T7: =SUMPRODUCT(('Monthly Occurrences (Support)'!$C$4:$C$166=$A7)*('Monthly Occurrences (Support)'!$D$4:$D$166="Physical")*('Monthly Occurrences (Support)'!$Y$4:$Y$166)) -> 0 | U7: =SUMPRODUCT(('Monthly Occurrences (Support)'!$C$4:$C$166=$A7)*('Monthly Occurrences (Support)'!$D$4:$D$166="Physical")*('Monthly Occurrences (Support)'!$Z$4:$Z$166)) -> 0 | V7: =SUMPRODUCT(('Monthly Occurrences (Support)'!$C$4:$C$166=$A7)*('Monthly Occurrences (Support)'!$D$4:$D$166="Physical")*('Monthly Occurrences (Support)'!$AA$4:$AA$166)) -> 0 | W7: =SUMPRODUCT(('Monthly Occurrences (Support)'!$C$4:$C$166=$A7)*('Monthly Occurrences (Support)'!$D$4:$D$166="Physical")*('Monthly Occurrences (Support)'!$AB$4:$AB$166)) -> 0
A8: EAST 305 | B8: =SUMPRODUCT(('Monthly Occurrences (Support)'!$C$4:$C$166=$A8)*('Monthly Occurrences (Support)'!$D$4:$D$166="Physical")*('Monthly Occurrences (Support)'!$G$4:$G$166)) -> 0 | C8: =SUMPRODUCT(('Monthly Occurrences (Support)'!$C$4:$C$166=$A8)*('Monthly Occurrences (Support)'!$D$4:$D$166="Physical")*('Monthly Occurrences (Support)'!$H$4:$H$166)) -> 0 | D8: =SUMPRODUCT(('Monthly Occurrences (Support)'!$C$4:$C$166=$A8)*('Monthly Occurrences (Support)'!$D$4:$D$166="Physical")*('Monthly Occurrences (Support)'!$I$4:$I$166)) -> 0 | E8: =SUMPRODUCT(('Monthly Occurrences (Support)'!$C$4:$C$166=$A8)*('Monthly Occurrences (Support)'!$D$4:$D$166="Physical")*('Monthly Occurrences (Support)'!$J$4:$J$166)) -> 0 | F8: =SUMPRODUCT(('Monthly Occurrences (Support)'!$C$4:$C$166=$A8)*('Monthly Occurrences (Support)'!$D$4:$D$166="Physical")*('Monthly Occurrences (Support)'!$K$4:$K$166)) -> 0 | G8: =SUMPRODUCT(('Monthly Occurrences (Support)'!$C$4:$C$166=$A8)*('Monthly Occurrences (Support)'!$D$4:$D$166="Physical")*('Monthly Occurrences (Support)'!$L$4:$L$166)) -> 0 | H8: =SUMPRODUCT(('Monthly Occurrences (Support)'!$C$4:$C$166=$A8)*('Monthly Occurrences (Support)'!$D$4:$D$166="Physical")*('Monthly Occurrences (Support)'!$M$4:$M$166)) -> 0 | I8: =SUMPRODUCT(('Monthly Occurrences (Support)'!$C$4:$C$166=$A8)*('Monthly Occurrences (Support)'!$D$4:$D$166="Physical")*('Monthly Occurrences (Support)'!$N$4:$N$166)) -> 0 | J8: =SUMPRODUCT(('Monthly Occurrences (Support)'!$C$4:$C$166=$A8)*('Monthly Occurrences (Support)'!$D$4:$D$166="Physical")*('Monthly Occurrences (Support)'!$O$4:$O$166)) -> 24 | K8: =SUMPRODUCT(('Monthly Occurrences (Support)'!$C$4:$C$166=$A8)*('Monthly Occurrences (Support)'!$D$4:$D$166="Physical")*('Monthly Occurrences (Support)'!$P$4:$P$166)) -> 34 | L8: =SUMPRODUCT(('Monthly Occurrences (Support)'!$C$4:$C$166=$A8)*('Monthly Occurrences (Support)'!$D$4:$D$166="Physical")*('Monthly Occurrences (Support)'!$Q$4:$Q$166)) -> 35 | M8: =SUMPRODUCT(('Monthly Occurrences (Support)'!$C$4:$C$166=$A8)*('Monthly Occurrences (Support)'!$D$4:$D$166="Physical")*('Monthly Occurrences (Support)'!$R$4:$R$166)) -> 35 | N8: =SUMPRODUCT(('Monthly Occurrences (Support)'!$C$4:$C$166=$A8)*('Monthly Occurrences (Support)'!$D$4:$D$166="Physical")*('Monthly Occurrences (Support)'!$S$4:$S$166)) -> 34 | O8: =SUMPRODUCT(('Monthly Occurrences (Support)'!$C$4:$C$166=$A8)*('Monthly Occurrences (Support)'!$D$4:$D$166="Physical")*('Monthly Occurrences (Support)'!$T$4:$T$166)) -> 37 | P8: =SUMPRODUCT(('Monthly Occurrences (Support)'!$C$4:$C$166=$A8)*('Monthly Occurrences (Support)'!$D$4:$D$166="Physical")*('Monthly Occurrences (Support)'!$U$4:$U$166)) -> 33 | Q8: =SUMPRODUCT(('Monthly Occurrences (Support)'!$C$4:$C$166=$A8)*('Monthly Occurrences (Support)'!$D$4:$D$166="Physical")*('Monthly Occurrences (Support)'!$V$4:$V$166)) -> 32 | R8: =SUMPRODUCT(('Monthly Occurrences (Support)'!$C$4:$C$166=$A8)*('Monthly Occurrences (Support)'!$D$4:$D$166="Physical")*('Monthly Occurrences (Support)'!$W$4:$W$166)) -> 37 | S8: =SUMPRODUCT(('Monthly Occurrences (Support)'!$C$4:$C$166=$A8)*('Monthly Occurrences (Support)'!$D$4:$D$166="Physical")*('Monthly Occurrences (Support)'!$X$4:$X$166)) -> 35 | T8: =SUMPRODUCT(('Monthly Occurrences (Support)'!$C$4:$C$166=$A8)*('Monthly Occurrences (Support)'!$D$4:$D$166="Physical")*('Monthly Occurrences (Support)'!$Y$4:$Y$166)) -> 34 | U8: =SUMPRODUCT(('Monthly Occurrences (Support)'!$C$4:$C$166=$A8)*('Monthly Occurrences (Support)'!$D$4:$D$166="Physical")*('Monthly Occurrences (Support)'!$Z$4:$Z$166)) -> 35 | V8: =SUMPRODUCT(('Monthly Occurrences (Support)'!$C$4:$C$166=$A8)*('Monthly Occurrences (Support)'!$D$4:$D$166="Physical")*('Monthly Occurrences (Support)'!$AA$4:$AA$166)) -> 35 | W8: =SUMPRODUCT(('Monthly Occurrences (Support)'!$C$4:$C$166=$A8)*('Monthly Occurrences (Support)'!$D$4:$D$166="Physical")*('Monthly Occurrences (Support)'!$AB$4:$AB$166)) -> 36
A9: EAST 306 | B9: =SUMPRODUCT(('Monthly Occurrences (Support)'!$C$4:$C$166=$A9)*('Monthly Occurrences (Support)'!$D$4:$D$166="Physical")*('Monthly Occurrences (Support)'!$G$4:$G$166)) -> 0 | C9: =SUMPRODUCT(('Monthly Occurrences (Support)'!$C$4:$C$166=$A9)*('Monthly Occurrences (Support)'!$D$4:$D$166="Physical")*('Monthly Occurrences (Support)'!$H$4:$H$166)) -> 0 | D9: =SUMPRODUCT(('Monthly Occurrences (Support)'!$C$4:$C$166=$A9)*('Monthly Occurrences (Support)'!$D$4:$D$166="Physical")*('Monthly Occurrences (Support)'!$I$4:$I$166)) -> 0 | E9: =SUMPRODUCT(('Monthly Occurrences (Support)'!$C$4:$C$166=$A9)*('Monthly Occurrences (Support)'!$D$4:$D$166="Physical")*('Monthly Occurrences (Support)'!$J$4:$J$166)) -> 0 | F9: =SUMPRODUCT(('Monthly Occurrences (Support)'!$C$4:$C$166=$A9)*('Monthly Occurrences (Support)'!$D$4:$D$166="Physical")*('Monthly Occurrences (Support)'!$K$4:$K$166)) -> 11 | G9: =SUMPRODUCT(('Monthly Occurrences (Support)'!$C$4:$C$166=$A9)*('Monthly Occurrences (Support)'!$D$4:$D$166="Physical")*('Monthly Occurrences (Support)'!$L$4:$L$166)) -> 17 | H9: =SUMPRODUCT(('Monthly Occurrences (Support)'!$C$4:$C$166=$A9)*('Monthly Occurrences (Support)'!$D$4:$D$166="Physical")*('Monthly Occurrences (Support)'!$M$4:$M$166)) -> 16 | I9: =SUMPRODUCT(('Monthly Occurrences (Support)'!$C$4:$C$166=$A9)*('Monthly Occurrences (Support)'!$D$4:$D$166="Physical")*('Monthly Occurrences (Support)'!$N$4:$N$166)) -> 19 | J9: =SUMPRODUCT(('Monthly Occurrences (Support)'!$C$4:$C$166=$A9)*('Monthly Occurrences (Support)'!$D$4:$D$166="Physical")*('Monthly Occurrences (Support)'!$O$4:$O$166)) -> 19 | K9: =SUMPRODUCT(('Monthly Occurrences (Support)'!$C$4:$C$166=$A9)*('Monthly Occurrences (Support)'!$D$4:$D$166="Physical")*('Monthly Occurrences (Support)'!$P$4:$P$166)) -> 9 | L9: =SUMPRODUCT(('Monthly Occurrences (Support)'!$C$4:$C$166=$A9)*('Monthly Occurrences (Support)'!$D$4:$D$166="Physical")*('Monthly Occurrences (Support)'!$Q$4:$Q$166)) -> 9 | M9: =SUMPRODUCT(('Monthly Occurrences (Support)'!$C$4:$C$166=$A9)*('Monthly Occurrences (Support)'!$D$4:$D$166="Physical")*('Monthly Occurrences (Support)'!$R$4:$R$166)) -> 9 | N9: =SUMPRODUCT(('Monthly Occurrences (Support)'!$C$4:$C$166=$A9)*('Monthly Occurrences (Support)'!$D$4:$D$166="Physical")*('Monthly Occurrences (Support)'!$S$4:$S$166)) -> 8 | O9: =SUMPRODUCT(('Monthly Occurrences (Support)'!$C$4:$C$166=$A9)*('Monthly Occurrences (Support)'!$D$4:$D$166="Physical")*('Monthly Occurrences (Support)'!$T$4:$T$166)) -> 3 | P9: =SUMPRODUCT(('Monthly Occurrences (Support)'!$C$4:$C$166=$A9)*('Monthly Occurrences (Support)'!$D$4:$D$166="Physical")*('Monthly Occurrences (Support)'!$U$4:$U$166)) -> 0 | Q9: =SUMPRODUCT(('Monthly Occurrences (Support)'!$C$4:$C$166=$A9)*('Monthly Occurrences (Support)'!$D$4:$D$166="Physical")*('Monthly Occurrences (Support)'!$V$4:$V$166)) -> 0 | R9: =SUMPRODUCT(('Monthly Occurrences (Support)'!$C$4:$C$166=$A9)*('Monthly Occurrences (Support)'!$D$4:$D$166="Physical")*('Monthly Occurrences (Support)'!$W$4:$W$166)) -> 0 | S9: =SUMPRODUCT(('Monthly Occurrences (Support)'!$C$4:$C$166=$A9)*('Monthly Occurrences (Support)'!$D$4:$D$166="Physical")*('Monthly Occurrences (Support)'!$X$4:$X$166)) -> 0 | T9: =SUMPRODUCT(('Monthly Occurrences (Support)'!$C$4:$C$166=$A9)*('Monthly Occurrences (Support)'!$D$4:$D$166="Physical")*('Monthly Occurrences (Support)'!$Y$4:$Y$166)) -> 0 | U9: =SUMPRODUCT(('Monthly Occurrences (Support)'!$C$4:$C$166=$A9)*('Monthly Occurrences (Support)'!$D$4:$D$166="Physical")*('Monthly Occurrences (Support)'!$Z$4:$Z$166)) -> 0 | V9: =SUMPRODUCT(('Monthly Occurrences (Support)'!$C$4:$C$166=$A9)*('Monthly Occurrences (Support)'!$D$4:$D$166="Physical")*('Monthly Occurrences (Support)'!$AA$4:$AA$166)) -> 0 | W9: =SUMPRODUCT(('Monthly Occurrences (Support)'!$C$4:$C$166=$A9)*('Monthly Occurrences (Support)'!$D$4:$D$166="Physical")*('Monthly Occurrences (Support)'!$AB$4:$AB$166)) -> 0
A10: EAST 307 | B10: =SUMPRODUCT(('Monthly Occurrences (Support)'!$C$4:$C$166=$A10)*('Monthly Occurrences (Support)'!$D$4:$D$166="Physical")*('Monthly Occurrences (Support)'!$G$4:$G$166)) -> 0 | C10: =SUMPRODUCT(('Monthly Occurrences (Support)'!$C$4:$C$166=$A10)*('Monthly Occurrences (Support)'!$D$4:$D$166="Physical")*('Monthly Occurrences (Support)'!$H$4:$H$166)) -> 0 | D10: =SUMPRODUCT(('Monthly Occurrences (Support)'!$C$4:$C$166=$A10)*('Monthly Occurrences (Support)'!$D$4:$D$166="Physical")*('Monthly Occurrences (Support)'!$I$4:$I$166)) -> 0 | E10: =SUMPRODUCT(('Monthly Occurrences (Support)'!$C$4:$C$166=$A10)*('Monthly Occurrences (Support)'!$D$4:$D$166="Physical")*('Monthly Occurrences (Support)'!$J$4:$J$166)) -> 0 | F10: =SUMPRODUCT(('Monthly Occurrences (Support)'!$C$4:$C$166=$A10)*('Monthly Occurrences (Support)'!$D$4:$D$166="Physical")*('Monthly Occurrences (Support)'!$K$4:$K$166)) -> 0 | G10: =SUMPRODUCT(('Monthly Occurrences (Support)'!$C$4:$C$166=$A10)*('Monthly Occurrences (Support)'!$D$4:$D$166="Physical")*('Monthly Occurrences (Support)'!$L$4:$L$166)) -> 0 | H10: =SUMPRODUCT(('Monthly Occurrences (Support)'!$C$4:$C$166=$A10)*('Monthly Occurrences (Support)'!$D$4:$D$166="Physical")*('Monthly Occurrences (Support)'!$M$4:$M$166)) -> 0 | I10: =SUMPRODUCT(('Monthly Occurrences (Support)'!$C$4:$C$166=$A10)*('Monthly Occurrences (Support)'!$D$4:$D$166="Physical")*('Monthly Occurrences (Support)'!$N$4:$N$166)) -> 0 | J10: =SUMPRODUCT(('Monthly Occurrences (Support)'!$C$4:$C$166=$A10)*('Monthly Occurrences (Support)'!$D$4:$D$166="Physical")*('Monthly Occurrences (Support)'!$O$4:$O$166)) -> 0 | K10: =SUMPRODUCT(('Monthly Occurrences (Support)'!$C$4:$C$166=$A10)*('Monthly Occurrences (Support)'!$D$4:$D$166="Physical")*('Monthly Occurrences (Support)'!$P$4:$P$166)) -> 0 | L10: =SUMPRODUCT(('Monthly Occurrences (Support)'!$C$4:$C$166=$A10)*('Monthly Occurrences (Support)'!$D$4:$D$166="Physical")*('Monthly Occurrences (Support)'!$Q$4:$Q$166)) -> 0 | M10: =SUMPRODUCT(('Monthly Occurrences (Support)'!$C$4:$C$166=$A10)*('Monthly Occurrences (Support)'!$D$4:$D$166="Physical")*('Monthly Occurrences (Support)'!$R$4:$R$166)) -> 0 | N10: =SUMPRODUCT(('Monthly Occurrences (Support)'!$C$4:$C$166=$A10)*('Monthly Occurrences (Support)'!$D$4:$D$166="Physical")*('Monthly Occurrences (Support)'!$S$4:$S$166)) -> 0 | O10: =SUMPRODUCT(('Monthly Occurrences (Support)'!$C$4:$C$166=$A10)*('Monthly Occurrences (Support)'!$D$4:$D$166="Physical")*('Monthly Occurrences (Support)'!$T$4:$T$166)) -> 0 | P10: =SUMPRODUCT(('Monthly Occurrences (Support)'!$C$4:$C$166=$A10)*('Monthly Occurrences (Support)'!$D$4:$D$166="Physical")*('Monthly Occurrences (Support)'!$U$4:$U$166)) -> 0 | Q10: =SUMPRODUCT(('Monthly Occurrences (Support)'!$C$4:$C$166=$A10)*('Monthly Occurrences (Support)'!$D$4:$D$166="Physical")*('Monthly Occurrences (Support)'!$V$4:$V$166)) -> 0 | R10: =SUMPRODUCT(('Monthly Occurrences (Support)'!$C$4:$C$166=$A10)*('Monthly Occurrences (Support)'!$D$4:$D$166="Physical")*('Monthly Occurrences (Support)'!$W$4:$W$166)) -> 0 | S10: =SUMPRODUCT(('Monthly Occurrences (Support)'!$C$4:$C$166=$A10)*('Monthly Occurrences (Support)'!$D$4:$D$166="Physical")*('Monthly Occurrences (Support)'!$X$4:$X$166)) -> 0 | T10: =SUMPRODUCT(('Monthly Occurrences (Support)'!$C$4:$C$166=$A10)*('Monthly Occurrences (Support)'!$D$4:$D$166="Physical")*('Monthly Occurrences (Support)'!$Y$4:$Y$166)) -> 0 | U10: =SUMPRODUCT(('Monthly Occurrences (Support)'!$C$4:$C$166=$A10)*('Monthly Occurrences (Support)'!$D$4:$D$166="Physical")*('Monthly Occurrences (Support)'!$Z$4:$Z$166)) -> 0 | V10: =SUMPRODUCT(('Monthly Occurrences (Support)'!$C$4:$C$166=$A10)*('Monthly Occurrences (Support)'!$D$4:$D$166="Physical")*('Monthly Occurrences (Support)'!$AA$4:$AA$166)) -> 0 | W10: =SUMPRODUCT(('Monthly Occurrences (Support)'!$C$4:$C$166=$A10)*('Monthly Occurrences (Support)'!$D$4:$D$166="Physical")*('Monthly Occurrences (Support)'!$AB$4:$AB$166)) -> 0
A11: KITCHEN | B11: =SUMPRODUCT(('Monthly Occurrences (Support)'!$C$4:$C$166=$A11)*('Monthly Occurrences (Support)'!$D$4:$D$166="Physical")*('Monthly Occurrences (Support)'!$G$4:$G$166)) -> 0 | C11: =SUMPRODUCT(('Monthly Occurrences (Support)'!$C$4:$C$166=$A11)*('Monthly Occurrences (Support)'!$D$4:$D$166="Physical")*('Monthly Occurrences (Support)'!$H$4:$H$166)) -> 0 | D11: =SUMPRODUCT(('Monthly Occurrences (Support)'!$C$4:$C$166=$A11)*('Monthly Occurrences (Support)'!$D$4:$D$166="Physical")*('Monthly Occurrences (Support)'!$I$4:$I$166)) -> 0 | E11: =SUMPRODUCT(('Monthly Occurrences (Support)'!$C$4:$C$166=$A11)*('Monthly Occurrences (Support)'!$D$4:$D$166="Physical")*('Monthly Occurrences (Support)'!$J$4:$J$166)) -> 0 | F11: =SUMPRODUCT(('Monthly Occurrences (Support)'!$C$4:$C$166=$A11)*('Monthly Occurrences (Support)'!$D$4:$D$166="Physical")*('Monthly Occurrences (Support)'!$K$4:$K$166)) -> 2 | G11: =SUMPRODUCT(('Monthly Occurrences (Support)'!$C$4:$C$166=$A11)*('Monthly Occurrences (Support)'!$D$4:$D$166="Physical")*('Monthly Occurrences (Support)'!$L$4:$L$166)) -> 5 | H11: =SUMPRODUCT(('Monthly Occurrences (Support)'!$C$4:$C$166=$A11)*('Monthly Occurrences (Support)'!$D$4:$D$166="Physical")*('Monthly Occurrences (Support)'!$M$4:$M$166)) -> 4 | I11: =SUMPRODUCT(('Monthly Occurrences (Support)'!$C$4:$C$166=$A11)*('Monthly Occurrences (Support)'!$D$4:$D$166="Physical")*('Monthly Occurrences (Support)'!$N$4:$N$166)) -> 4 | J11: =SUMPRODUCT(('Monthly Occurrences (Support)'!$C$4:$C$166=$A11)*('Monthly Occurrences (Support)'!$D$4:$D$166="Physical")*('Monthly Occurrences (Support)'!$O$4:$O$166)) -> 4 | K11: =SUMPRODUCT(('Monthly Occurrences (Support)'!$C$4:$C$166=$A11)*('Monthly Occurrences (Support)'!$D$4:$D$166="Physical")*('Monthly Occurrences (Support)'!$P$4:$P$166)) -> 0 | L11: =SUMPRODUCT(('Monthly Occurrences (Support)'!$C$4:$C$166=$A11)*('Monthly Occurrences (Support)'!$D$4:$D$166="Physical")*('Monthly Occurrences (Support)'!$Q$4:$Q$166)) -> 0 | M11: =SUMPRODUCT(('Monthly Occurrences (Support)'!$C$4:$C$166=$A11)*('Monthly Occurrences (Support)'!$D$4:$D$166="Physical")*('Monthly Occurrences (Support)'!$R$4:$R$166)) -> 0 | N11: =SUMPRODUCT(('Monthly Occurrences (Support)'!$C$4:$C$166=$A11)*('Monthly Occurrences (Support)'!$D$4:$D$166="Physical")*('Monthly Occurrences (Support)'!$S$4:$S$166)) -> 0 | O11: =SUMPRODUCT(('Monthly Occurrences (Support)'!$C$4:$C$166=$A11)*('Monthly Occurrences (Support)'!$D$4:$D$166="Physical")*('Monthly Occurrences (Support)'!$T$4:$T$166)) -> 0 | P11: =SUMPRODUCT(('Monthly Occurrences (Support)'!$C$4:$C$166=$A11)*('Monthly Occurrences (Support)'!$D$4:$D$166="Physical")*('Monthly Occurrences (Support)'!$U$4:$U$166)) -> 0 | Q11: =SUMPRODUCT(('Monthly Occurrences (Support)'!$C$4:$C$166=$A11)*('Monthly Occurrences (Support)'!$D$4:$D$166="Physical")*('Monthly Occurrences (Support)'!$V$4:$V$166)) -> 0 | R11: =SUMPRODUCT(('Monthly Occurrences (Support)'!$C$4:$C$166=$A11)*('Monthly Occurrences (Support)'!$D$4:$D$166="Physical")*('Monthly Occurrences (Support)'!$W$4:$W$166)) -> 0 | S11: =SUMPRODUCT(('Monthly Occurrences (Support)'!$C$4:$C$166=$A11)*('Monthly Occurrences (Support)'!$D$4:$D$166="Physical")*('Monthly Occurrences (Support)'!$X$4:$X$166)) -> 0 | T11: =SUMPRODUCT(('Monthly Occurrences (Support)'!$C$4:$C$166=$A11)*('Monthly Occurrences (Support)'!$D$4:$D$166="Physical")*('Monthly Occurrences (Support)'!$Y$4:$Y$166)) -> 0 | U11: =SUMPRODUCT(('Monthly Occurrences (Support)'!$C$4:$C$166=$A11)*('Monthly Occurrences (Support)'!$D$4:$D$166="Physical")*('Monthly Occurrences (Support)'!$Z$4:$Z$166)) -> 0 | V11: =SUMPRODUCT(('Monthly Occurrences (Support)'!$C$4:$C$166=$A11)*('Monthly Occurrences (Support)'!$D$4:$D$166="Physical")*('Monthly Occurrences (Support)'!$AA$4:$AA$166)) -> 0 | W11: =SUMPRODUCT(('Monthly Occurrences (Support)'!$C$4:$C$166=$A11)*('Monthly Occurrences (Support)'!$D$4:$D$166="Physical")*('Monthly Occurrences (Support)'!$AB$4:$AB$166)) -> 0
A12: Library | B12: =SUMPRODUCT(('Monthly Occurrences (Support)'!$C$4:$C$166=$A12)*('Monthly Occurrences (Support)'!$D$4:$D$166="Physical")*('Monthly Occurrences (Support)'!$G$4:$G$166)) -> 0 | C12: =SUMPRODUCT(('Monthly Occurrences (Support)'!$C$4:$C$166=$A12)*('Monthly Occurrences (Support)'!$D$4:$D$166="Physical")*('Monthly Occurrences (Support)'!$H$4:$H$166)) -> 0 | D12: =SUMPRODUCT(('Monthly Occurrences (Support)'!$C$4:$C$166=$A12)*('Monthly Occurrences (Support)'!$D$4:$D$166="Physical")*('Monthly Occurrences (Support)'!$I$4:$I$166)) -> 0 | E12: =SUMPRODUCT(('Monthly Occurrences (Support)'!$C$4:$C$166=$A12)*('Monthly Occurrences (Support)'!$D$4:$D$166="Physical")*('Monthly Occurrences (Support)'!$J$4:$J$166)) -> 0 | F12: =SUMPRODUCT(('Monthly Occurrences (Support)'!$C$4:$C$166=$A12)*('Monthly Occurrences (Support)'!$D$4:$D$166="Physical")*('Monthly Occurrences (Support)'!$K$4:$K$166)) -> 0 | G12: =SUMPRODUCT(('Monthly Occurrences (Support)'!$C$4:$C$166=$A12)*('Monthly Occurrences (Support)'!$D$4:$D$166="Physical")*('Monthly Occurrences (Support)'!$L$4:$L$166)) -> 0 | H12: =SUMPRODUCT(('Monthly Occurrences (Support)'!$C$4:$C$166=$A12)*('Monthly Occurrences (Support)'!$D$4:$D$166="Physical")*('Monthly Occurrences (Support)'!$M$4:$M$166)) -> 0 | I12: =SUMPRODUCT(('Monthly Occurrences (Support)'!$C$4:$C$166=$A12)*('Monthly Occurrences (Support)'!$D$4:$D$166="Physical")*('Monthly Occurrences (Support)'!$N$4:$N$166)) -> 0 | J12: =SUMPRODUCT(('Monthly Occurrences (Support)'!$C$4:$C$166=$A12)*('Monthly Occurrences (Support)'!$D$4:$D$166="Physical")*('Monthly Occurrences (Support)'!$O$4:$O$166)) -> 0 | K12: =SUMPRODUCT(('Monthly Occurrences (Support)'!$C$4:$C$166=$A12)*('Monthly Occurrences (Support)'!$D$4:$D$166="Physical")*('Monthly Occurrences (Support)'!$P$4:$P$166)) -> 0 | L12: =SUMPRODUCT(('Monthly Occurrences (Support)'!$C$4:$C$166=$A12)*('Monthly Occurrences (Support)'!$D$4:$D$166="Physical")*('Monthly Occurrences (Support)'!$Q$4:$Q$166)) -> 0 | M12: =SUMPRODUCT(('Monthly Occurrences (Support)'!$C$4:$C$166=$A12)*('Monthly Occurrences (Support)'!$D$4:$D$166="Physical")*('Monthly Occurrences (Support)'!$R$4:$R$166)) -> 0 | N12: =SUMPRODUCT(('Monthly Occurrences (Support)'!$C$4:$C$166=$A12)*('Monthly Occurrences (Support)'!$D$4:$D$166="Physical")*('Monthly Occurrences (Support)'!$S$4:$S$166)) -> 0 | O12: =SUMPRODUCT(('Monthly Occurrences (Support)'!$C$4:$C$166=$A12)*('Monthly Occurrences (Support)'!$D$4:$D$166="Physical")*('Monthly Occurrences (Support)'!$T$4:$T$166)) -> 0 | P12: =SUMPRODUCT(('Monthly Occurrences (Support)'!$C$4:$C$166=$A12)*('Monthly Occurrences (Support)'!$D$4:$D$166="Physical")*('Monthly Occurrences (Support)'!$U$4:$U$166)) -> 0 | Q12: =SUMPRODUCT(('Monthly Occurrences (Support)'!$C$4:$C$166=$A12)*('Monthly Occurrences (Support)'!$D$4:$D$166="Physical")*('Monthly Occurrences (Support)'!$V$4:$V$166)) -> 0 | R12: =SUMPRODUCT(('Monthly Occurrences (Support)'!$C$4:$C$166=$A12)*('Monthly Occurrences (Support)'!$D$4:$D$166="Physical")*('Monthly Occurrences (Support)'!$W$4:$W$166)) -> 0 | S12: =SUMPRODUCT(('Monthly Occurrences (Support)'!$C$4:$C$166=$A12)*('Monthly Occurrences (Support)'!$D$4:$D$166="Physical")*('Monthly Occurrences (Support)'!$X$4:$X$166)) -> 0 | T12: =SUMPRODUCT(('Monthly Occurrences (Support)'!$C$4:$C$166=$A12)*('Monthly Occurrences (Support)'!$D$4:$D$166="Physical")*('Monthly Occurrences (Support)'!$Y$4:$Y$166)) -> 0 | U12: =SUMPRODUCT(('Monthly Occurrences (Support)'!$C$4:$C$166=$A12)*('Monthly Occurrences (Support)'!$D$4:$D$166="Physical")*('Monthly Occurrences (Support)'!$Z$4:$Z$166)) -> 0 | V12: =SUMPRODUCT(('Monthly Occurrences (Support)'!$C$4:$C$166=$A12)*('Monthly Occurrences (Support)'!$D$4:$D$166="Physical")*('Monthly Occurrences (Support)'!$AA$4:$AA$166)) -> 0 | W12: =SUMPRODUCT(('Monthly Occurrences (Support)'!$C$4:$C$166=$A12)*('Monthly Occurrences (Support)'!$D$4:$D$166="Physical")*('Monthly Occurrences (Support)'!$AB$4:$AB$166)) -> 0
A13: MAIN BOARD ROOM | B13: =SUMPRODUCT(('Monthly Occurrences (Support)'!$C$4:$C$166=$A13)*('Monthly Occurrences (Support)'!$D$4:$D$166="Physical")*('Monthly Occurrences (Support)'!$G$4:$G$166)) -> 0 | C13: =SUMPRODUCT(('Monthly Occurrences (Support)'!$C$4:$C$166=$A13)*('Monthly Occurrences (Support)'!$D$4:$D$166="Physical")*('Monthly Occurrences (Support)'!$H$4:$H$166)) -> 0 | D13: =SUMPRODUCT(('Monthly Occurrences (Support)'!$C$4:$C$166=$A13)*('Monthly Occurrences (Support)'!$D$4:$D$166="Physical")*('Monthly Occurrences (Support)'!$I$4:$I$166)) -> 0 | E13: =SUMPRODUCT(('Monthly Occurrences (Support)'!$C$4:$C$166=$A13)*('Monthly Occurrences (Support)'!$D$4:$D$166="Physical")*('Monthly Occurrences (Support)'!$J$4:$J$166)) -> 0 | F13: =SUMPRODUCT(('Monthly Occurrences (Support)'!$C$4:$C$166=$A13)*('Monthly Occurrences (Support)'!$D$4:$D$166="Physical")*('Monthly Occurrences (Support)'!$K$4:$K$166)) -> 0 | G13: =SUMPRODUCT(('Monthly Occurrences (Support)'!$C$4:$C$166=$A13)*('Monthly Occurrences (Support)'!$D$4:$D$166="Physical")*('Monthly Occurrences (Support)'!$L$4:$L$166)) -> 4 | H13: =SUMPRODUCT(('Monthly Occurrences (Support)'!$C$4:$C$166=$A13)*('Monthly Occurrences (Support)'!$D$4:$D$166="Physical")*('Monthly Occurrences (Support)'!$M$4:$M$166)) -> 5 | I13: =SUMPRODUCT(('Monthly Occurrences (Support)'!$C$4:$C$166=$A13)*('Monthly Occurrences (Support)'!$D$4:$D$166="Physical")*('Monthly Occurrences (Support)'!$N$4:$N$166)) -> 7 | J13: =SUMPRODUCT(('Monthly Occurrences (Support)'!$C$4:$C$166=$A13)*('Monthly Occurrences (Support)'!$D$4:$D$166="Physical")*('Monthly Occurrences (Support)'!$O$4:$O$166)) -> 8 | K13: =SUMPRODUCT(('Monthly Occurrences (Support)'!$C$4:$C$166=$A13)*('Monthly Occurrences (Support)'!$D$4:$D$166="Physical")*('Monthly Occurrences (Support)'!$P$4:$P$166)) -> 10 | L13: =SUMPRODUCT(('Monthly Occurrences (Support)'!$C$4:$C$166=$A13)*('Monthly Occurrences (Support)'!$D$4:$D$166="Physical")*('Monthly Occurrences (Support)'!$Q$4:$Q$166)) -> 7 | M13: =SUMPRODUCT(('Monthly Occurrences (Support)'!$C$4:$C$166=$A13)*('Monthly Occurrences (Support)'!$D$4:$D$166="Physical")*('Monthly Occurrences (Support)'!$R$4:$R$166)) -> 5 | N13: =SUMPRODUCT(('Monthly Occurrences (Support)'!$C$4:$C$166=$A13)*('Monthly Occurrences (Support)'!$D$4:$D$166="Physical")*('Monthly Occurrences (Support)'!$S$4:$S$166)) -> 4 | O13: =SUMPRODUCT(('Monthly Occurrences (Support)'!$C$4:$C$166=$A13)*('Monthly Occurrences (Support)'!$D$4:$D$166="Physical")*('Monthly Occurrences (Support)'!$T$4:$T$166)) -> 0 | P13: =SUMPRODUCT(('Monthly Occurrences (Support)'!$C$4:$C$166=$A13)*('Monthly Occurrences (Support)'!$D$4:$D$166="Physical")*('Monthly Occurrences (Support)'!$U$4:$U$166)) -> 0 | Q13: =SUMPRODUCT(('Monthly Occurrences (Support)'!$C$4:$C$166=$A13)*('Monthly Occurrences (Support)'!$D$4:$D$166="Physical")*('Monthly Occurrences (Support)'!$V$4:$V$166)) -> 0 | R13: =SUMPRODUCT(('Monthly Occurrences (Support)'!$C$4:$C$166=$A13)*('Monthly Occurrences (Support)'!$D$4:$D$166="Physical")*('Monthly Occurrences (Support)'!$W$4:$W$166)) -> 0 | S13: =SUMPRODUCT(('Monthly Occurrences (Support)'!$C$4:$C$166=$A13)*('Monthly Occurrences (Support)'!$D$4:$D$166="Physical")*('Monthly Occurrences (Support)'!$X$4:$X$166)) -> 0 | T13: =SUMPRODUCT(('Monthly Occurrences (Support)'!$C$4:$C$166=$A13)*('Monthly Occurrences (Support)'!$D$4:$D$166="Physical")*('Monthly Occurrences (Support)'!$Y$4:$Y$166)) -> 0 | U13: =SUMPRODUCT(('Monthly Occurrences (Support)'!$C$4:$C$166=$A13)*('Monthly Occurrences (Support)'!$D$4:$D$166="Physical")*('Monthly Occurrences (Support)'!$Z$4:$Z$166)) -> 0 | V13: =SUMPRODUCT(('Monthly Occurrences (Support)'!$C$4:$C$166=$A13)*('Monthly Occurrences (Support)'!$D$4:$D$166="Physical")*('Monthly Occurrences (Support)'!$AA$4:$AA$166)) -> 0 | W13: =SUMPRODUCT(('Monthly Occurrences (Support)'!$C$4:$C$166=$A13)*('Monthly Occurrences (Support)'!$D$4:$D$166="Physical")*('Monthly Occurrences (Support)'!$AB$4:$AB$166)) -> 0
A14: MINI BOARD ROOM | B14: =SUMPRODUCT(('Monthly Occurrences (Support)'!$C$4:$C$166=$A14)*('Monthly Occurrences (Support)'!$D$4:$D$166="Physical")*('Monthly Occurrences (Support)'!$G$4:$G$166)) -> 0 | C14: =SUMPRODUCT(('Monthly Occurrences (Support)'!$C$4:$C$166=$A14)*('Monthly Occurrences (Support)'!$D$4:$D$166="Physical")*('Monthly Occurrences (Support)'!$H$4:$H$166)) -> 0 | D14: =SUMPRODUCT(('Monthly Occurrences (Support)'!$C$4:$C$166=$A14)*('Monthly Occurrences (Support)'!$D$4:$D$166="Physical")*('Monthly Occurrences (Support)'!$I$4:$I$166)) -> 0 | E14: =SUMPRODUCT(('Monthly Occurrences (Support)'!$C$4:$C$166=$A14)*('Monthly Occurrences (Support)'!$D$4:$D$166="Physical")*('Monthly Occurrences (Support)'!$J$4:$J$166)) -> 0 | F14: =SUMPRODUCT(('Monthly Occurrences (Support)'!$C$4:$C$166=$A14)*('Monthly Occurrences (Support)'!$D$4:$D$166="Physical")*('Monthly Occurrences (Support)'!$K$4:$K$166)) -> 0 | G14: =SUMPRODUCT(('Monthly Occurrences (Support)'!$C$4:$C$166=$A14)*('Monthly Occurrences (Support)'!$D$4:$D$166="Physical")*('Monthly Occurrences (Support)'!$L$4:$L$166)) -> 0 | H14: =SUMPRODUCT(('Monthly Occurrences (Support)'!$C$4:$C$166=$A14)*('Monthly Occurrences (Support)'!$D$4:$D$166="Physical")*('Monthly Occurrences (Support)'!$M$4:$M$166)) -> 0 | I14: =SUMPRODUCT(('Monthly Occurrences (Support)'!$C$4:$C$166=$A14)*('Monthly Occurrences (Support)'!$D$4:$D$166="Physical")*('Monthly Occurrences (Support)'!$N$4:$N$166)) -> 0 | J14: =SUMPRODUCT(('Monthly Occurrences (Support)'!$C$4:$C$166=$A14)*('Monthly Occurrences (Support)'!$D$4:$D$166="Physical")*('Monthly Occurrences (Support)'!$O$4:$O$166)) -> 1 | K14: =SUMPRODUCT(('Monthly Occurrences (Support)'!$C$4:$C$166=$A14)*('Monthly Occurrences (Support)'!$D$4:$D$166="Physical")*('Monthly Occurrences (Support)'!$P$4:$P$166)) -> 5 | L14: =SUMPRODUCT(('Monthly Occurrences (Support)'!$C$4:$C$166=$A14)*('Monthly Occurrences (Support)'!$D$4:$D$166="Physical")*('Monthly Occurrences (Support)'!$Q$4:$Q$166)) -> 4 | M14: =SUMPRODUCT(('Monthly Occurrences (Support)'!$C$4:$C$166=$A14)*('Monthly Occurrences (Support)'!$D$4:$D$166="Physical")*('Monthly Occurrences (Support)'!$R$4:$R$166)) -> 4 | N14: =SUMPRODUCT(('Monthly Occurrences (Support)'!$C$4:$C$166=$A14)*('Monthly Occurrences (Support)'!$D$4:$D$166="Physical")*('Monthly Occurrences (Support)'!$S$4:$S$166)) -> 5 | O14: =SUMPRODUCT(('Monthly Occurrences (Support)'!$C$4:$C$166=$A14)*('Monthly Occurrences (Support)'!$D$4:$D$166="Physical")*('Monthly Occurrences (Support)'!$T$4:$T$166)) -> 4 | P14: =SUMPRODUCT(('Monthly Occurrences (Support)'!$C$4:$C$166=$A14)*('Monthly Occurrences (Support)'!$D$4:$D$166="Physical")*('Monthly Occurrences (Support)'!$U$4:$U$166)) -> 2 | Q14: =SUMPRODUCT(('Monthly Occurrences (Support)'!$C$4:$C$166=$A14)*('Monthly Occurrences (Support)'!$D$4:$D$166="Physical")*('Monthly Occurrences (Support)'!$V$4:$V$166)) -> 0 | R14: =SUMPRODUCT(('Monthly Occurrences (Support)'!$C$4:$C$166=$A14)*('Monthly Occurrences (Support)'!$D$4:$D$166="Physical")*('Monthly Occurrences (Support)'!$W$4:$W$166)) -> 0 | S14: =SUMPRODUCT(('Monthly Occurrences (Support)'!$C$4:$C$166=$A14)*('Monthly Occurrences (Support)'!$D$4:$D$166="Physical")*('Monthly Occurrences (Support)'!$X$4:$X$166)) -> 0 | T14: =SUMPRODUCT(('Monthly Occurrences (Support)'!$C$4:$C$166=$A14)*('Monthly Occurrences (Support)'!$D$4:$D$166="Physical")*('Monthly Occurrences (Support)'!$Y$4:$Y$166)) -> 0 | U14: =SUMPRODUCT(('Monthly Occurrences (Support)'!$C$4:$C$166=$A14)*('Monthly Occurrences (Support)'!$D$4:$D$166="Physical")*('Monthly Occurrences (Support)'!$Z$4:$Z$166)) -> 0 | V14: =SUMPRODUCT(('Monthly Occurrences (Support)'!$C$4:$C$166=$A14)*('Monthly Occurrences (Support)'!$D$4:$D$166="Physical")*('Monthly Occurrences (Support)'!$AA$4:$AA$166)) -> 0 | W14: =SUMPRODUCT(('Monthly Occurrences (Support)'!$C$4:$C$166=$A14)*('Monthly Occurrences (Support)'!$D$4:$D$166="Physical")*('Monthly Occurrences (Support)'!$AB$4:$AB$166)) -> 0
A15: Next to Prof. Cabin | B15: =SUMPRODUCT(('Monthly Occurrences (Support)'!$C$4:$C$166=$A15)*('Monthly Occurrences (Support)'!$D$4:$D$166="Physical")*('Monthly Occurrences (Support)'!$G$4:$G$166)) -> 0 | C15: =SUMPRODUCT(('Monthly Occurrences (Support)'!$C$4:$C$166=$A15)*('Monthly Occurrences (Support)'!$D$4:$D$166="Physical")*('Monthly Occurrences (Support)'!$H$4:$H$166)) -> 0 | D15: =SUMPRODUCT(('Monthly Occurrences (Support)'!$C$4:$C$166=$A15)*('Monthly Occurrences (Support)'!$D$4:$D$166="Physical")*('Monthly Occurrences (Support)'!$I$4:$I$166)) -> 0 | E15: =SUMPRODUCT(('Monthly Occurrences (Support)'!$C$4:$C$166=$A15)*('Monthly Occurrences (Support)'!$D$4:$D$166="Physical")*('Monthly Occurrences (Support)'!$J$4:$J$166)) -> 0 | F15: =SUMPRODUCT(('Monthly Occurrences (Support)'!$C$4:$C$166=$A15)*('Monthly Occurrences (Support)'!$D$4:$D$166="Physical")*('Monthly Occurrences (Support)'!$K$4:$K$166)) -> 0 | G15: =SUMPRODUCT(('Monthly Occurrences (Support)'!$C$4:$C$166=$A15)*('Monthly Occurrences (Support)'!$D$4:$D$166="Physical")*('Monthly Occurrences (Support)'!$L$4:$L$166)) -> 0 | H15: =SUMPRODUCT(('Monthly Occurrences (Support)'!$C$4:$C$166=$A15)*('Monthly Occurrences (Support)'!$D$4:$D$166="Physical")*('Monthly Occurrences (Support)'!$M$4:$M$166)) -> 0 | I15: =SUMPRODUCT(('Monthly Occurrences (Support)'!$C$4:$C$166=$A15)*('Monthly Occurrences (Support)'!$D$4:$D$166="Physical")*('Monthly Occurrences (Support)'!$N$4:$N$166)) -> 0 | J15: =SUMPRODUCT(('Monthly Occurrences (Support)'!$C$4:$C$166=$A15)*('Monthly Occurrences (Support)'!$D$4:$D$166="Physical")*('Monthly Occurrences (Support)'!$O$4:$O$166)) -> 0 | K15: =SUMPRODUCT(('Monthly Occurrences (Support)'!$C$4:$C$166=$A15)*('Monthly Occurrences (Support)'!$D$4:$D$166="Physical")*('Monthly Occurrences (Support)'!$P$4:$P$166)) -> 0 | L15: =SUMPRODUCT(('Monthly Occurrences (Support)'!$C$4:$C$166=$A15)*('Monthly Occurrences (Support)'!$D$4:$D$166="Physical")*('Monthly Occurrences (Support)'!$Q$4:$Q$166)) -> 0 | M15: =SUMPRODUCT(('Monthly Occurrences (Support)'!$C$4:$C$166=$A15)*('Monthly Occurrences (Support)'!$D$4:$D$166="Physical")*('Monthly Occurrences (Support)'!$R$4:$R$166)) -> 0 | N15: =SUMPRODUCT(('Monthly Occurrences (Support)'!$C$4:$C$166=$A15)*('Monthly Occurrences (Support)'!$D$4:$D$166="Physical")*('Monthly Occurrences (Support)'!$S$4:$S$166)) -> 0 | O15: =SUMPRODUCT(('Monthly Occurrences (Support)'!$C$4:$C$166=$A15)*('Monthly Occurrences (Support)'!$D$4:$D$166="Physical")*('Monthly Occurrences (Support)'!$T$4:$T$166)) -> 0 | P15: =SUMPRODUCT(('Monthly Occurrences (Support)'!$C$4:$C$166=$A15)*('Monthly Occurrences (Support)'!$D$4:$D$166="Physical")*('Monthly Occurrences (Support)'!$U$4:$U$166)) -> 0 | Q15: =SUMPRODUCT(('Monthly Occurrences (Support)'!$C$4:$C$166=$A15)*('Monthly Occurrences (Support)'!$D$4:$D$166="Physical")*('Monthly Occurrences (Support)'!$V$4:$V$166)) -> 0 | R15: =SUMPRODUCT(('Monthly Occurrences (Support)'!$C$4:$C$166=$A15)*('Monthly Occurrences (Support)'!$D$4:$D$166="Physical")*('Monthly Occurrences (Support)'!$W$4:$W$166)) -> 0 | S15: =SUMPRODUCT(('Monthly Occurrences (Support)'!$C$4:$C$166=$A15)*('Monthly Occurrences (Support)'!$D$4:$D$166="Physical")*('Monthly Occurrences (Support)'!$X$4:$X$166)) -> 0 | T15: =SUMPRODUCT(('Monthly Occurrences (Support)'!$C$4:$C$166=$A15)*('Monthly Occurrences (Support)'!$D$4:$D$166="Physical")*('Monthly Occurrences (Support)'!$Y$4:$Y$166)) -> 0 | U15: =SUMPRODUCT(('Monthly Occurrences (Support)'!$C$4:$C$166=$A15)*('Monthly Occurrences (Support)'!$D$4:$D$166="Physical")*('Monthly Occurrences (Support)'!$Z$4:$Z$166)) -> 0 | V15: =SUMPRODUCT(('Monthly Occurrences (Support)'!$C$4:$C$166=$A15)*('Monthly Occurrences (Support)'!$D$4:$D$166="Physical")*('Monthly Occurrences (Support)'!$AA$4:$AA$166)) -> 0 | W15: =SUMPRODUCT(('Monthly Occurrences (Support)'!$C$4:$C$166=$A15)*('Monthly Occurrences (Support)'!$D$4:$D$166="Physical")*('Monthly Occurrences (Support)'!$AB$4:$AB$166)) -> 0
A16: TECH 001 | B16: =SUMPRODUCT(('Monthly Occurrences (Support)'!$C$4:$C$166=$A16)*('Monthly Occurrences (Support)'!$D$4:$D$166="Physical")*('Monthly Occurrences (Support)'!$G$4:$G$166)) -> 4 | C16: =SUMPRODUCT(('Monthly Occurrences (Support)'!$C$4:$C$166=$A16)*('Monthly Occurrences (Support)'!$D$4:$D$166="Physical")*('Monthly Occurrences (Support)'!$H$4:$H$166)) -> 4 | D16: =SUMPRODUCT(('Monthly Occurrences (Support)'!$C$4:$C$166=$A16)*('Monthly Occurrences (Support)'!$D$4:$D$166="Physical")*('Monthly Occurrences (Support)'!$I$4:$I$166)) -> 5 | E16: =SUMPRODUCT(('Monthly Occurrences (Support)'!$C$4:$C$166=$A16)*('Monthly Occurrences (Support)'!$D$4:$D$166="Physical")*('Monthly Occurrences (Support)'!$J$4:$J$166)) -> 4 | F16: =SUMPRODUCT(('Monthly Occurrences (Support)'!$C$4:$C$166=$A16)*('Monthly Occurrences (Support)'!$D$4:$D$166="Physical")*('Monthly Occurrences (Support)'!$K$4:$K$166)) -> 4 | G16: =SUMPRODUCT(('Monthly Occurrences (Support)'!$C$4:$C$166=$A16)*('Monthly Occurrences (Support)'!$D$4:$D$166="Physical")*('Monthly Occurrences (Support)'!$L$4:$L$166)) -> 5 | H16: =SUMPRODUCT(('Monthly Occurrences (Support)'!$C$4:$C$166=$A16)*('Monthly Occurrences (Support)'!$D$4:$D$166="Physical")*('Monthly Occurrences (Support)'!$M$4:$M$166)) -> 9 | I16: =SUMPRODUCT(('Monthly Occurrences (Support)'!$C$4:$C$166=$A16)*('Monthly Occurrences (Support)'!$D$4:$D$166="Physical")*('Monthly Occurrences (Support)'!$N$4:$N$166)) -> 13 | J16: =SUMPRODUCT(('Monthly Occurrences (Support)'!$C$4:$C$166=$A16)*('Monthly Occurrences (Support)'!$D$4:$D$166="Physical")*('Monthly Occurrences (Support)'!$O$4:$O$166)) -> 36 | K16: =SUMPRODUCT(('Monthly Occurrences (Support)'!$C$4:$C$166=$A16)*('Monthly Occurrences (Support)'!$D$4:$D$166="Physical")*('Monthly Occurrences (Support)'!$P$4:$P$166)) -> 43 | L16: =SUMPRODUCT(('Monthly Occurrences (Support)'!$C$4:$C$166=$A16)*('Monthly Occurrences (Support)'!$D$4:$D$166="Physical")*('Monthly Occurrences (Support)'!$Q$4:$Q$166)) -> 38 | M16: =SUMPRODUCT(('Monthly Occurrences (Support)'!$C$4:$C$166=$A16)*('Monthly Occurrences (Support)'!$D$4:$D$166="Physical")*('Monthly Occurrences (Support)'!$R$4:$R$166)) -> 39 | N16: =SUMPRODUCT(('Monthly Occurrences (Support)'!$C$4:$C$166=$A16)*('Monthly Occurrences (Support)'!$D$4:$D$166="Physical")*('Monthly Occurrences (Support)'!$S$4:$S$166)) -> 3 | O16: =SUMPRODUCT(('Monthly Occurrences (Support)'!$C$4:$C$166=$A16)*('Monthly Occurrences (Support)'!$D$4:$D$166="Physical")*('Monthly Occurrences (Support)'!$T$4:$T$166)) -> 0 | P16: =SUMPRODUCT(('Monthly Occurrences (Support)'!$C$4:$C$166=$A16)*('Monthly Occurrences (Support)'!$D$4:$D$166="Physical")*('Monthly Occurrences (Support)'!$U$4:$U$166)) -> 0 | Q16: =SUMPRODUCT(('Monthly Occurrences (Support)'!$C$4:$C$166=$A16)*('Monthly Occurrences (Support)'!$D$4:$D$166="Physical")*('Monthly Occurrences (Support)'!$V$4:$V$166)) -> 0 | R16: =SUMPRODUCT(('Monthly Occurrences (Support)'!$C$4:$C$166=$A16)*('Monthly Occurrences (Support)'!$D$4:$D$166="Physical")*('Monthly Occurrences (Support)'!$W$4:$W$166)) -> 0 | S16: =SUMPRODUCT(('Monthly Occurrences (Support)'!$C$4:$C$166=$A16)*('Monthly Occurrences (Support)'!$D$4:$D$166="Physical")*('Monthly Occurrences (Support)'!$X$4:$X$166)) -> 0 | T16: =SUMPRODUCT(('Monthly Occurrences (Support)'!$C$4:$C$166=$A16)*('Monthly Occurrences (Support)'!$D$4:$D$166="Physical")*('Monthly Occurrences (Support)'!$Y$4:$Y$166)) -> 0 | U16: =SUMPRODUCT(('Monthly Occurrences (Support)'!$C$4:$C$166=$A16)*('Monthly Occurrences (Support)'!$D$4:$D$166="Physical")*('Monthly Occurrences (Support)'!$Z$4:$Z$166)) -> 0 | V16: =SUMPRODUCT(('Monthly Occurrences (Support)'!$C$4:$C$166=$A16)*('Monthly Occurrences (Support)'!$D$4:$D$166="Physical")*('Monthly Occurrences (Support)'!$AA$4:$AA$166)) -> 0 | W16: =SUMPRODUCT(('Monthly Occurrences (Support)'!$C$4:$C$166=$A16)*('Monthly Occurrences (Support)'!$D$4:$D$166="Physical")*('Monthly Occurrences (Support)'!$AB$4:$AB$166)) -> 0
